Traceback (most recent call last):
  File "/home/nilomr/miniconda3/envs/pykanto-test/lib/python3.8/site-packages/jupyter_cache/executors/utils.py", line 51, in single_nb_execution
    executenb(
  File "/home/nilomr/miniconda3/envs/pykanto-test/lib/python3.8/site-packages/nbclient/client.py", line 1204, in execute
    return NotebookClient(nb=nb, resources=resources, km=km, **kwargs).execute()
  File "/home/nilomr/miniconda3/envs/pykanto-test/lib/python3.8/site-packages/nbclient/util.py", line 84, in wrapped
    return just_run(coro(*args, **kwargs))
  File "/home/nilomr/miniconda3/envs/pykanto-test/lib/python3.8/site-packages/nbclient/util.py", line 62, in just_run
    return loop.run_until_complete(coro)
  File "/home/nilomr/miniconda3/envs/pykanto-test/lib/python3.8/asyncio/base_events.py", line 608, in run_until_complete
    return future.result()
  File "/home/nilomr/miniconda3/envs/pykanto-test/lib/python3.8/site-packages/nbclient/client.py", line 663, in async_execute
    await self.async_execute_cell(
  File "/home/nilomr/miniconda3/envs/pykanto-test/lib/python3.8/site-packages/nbclient/client.py", line 965, in async_execute_cell
    await self._check_raise_for_error(cell, cell_index, exec_reply)
  File "/home/nilomr/miniconda3/envs/pykanto-test/lib/python3.8/site-packages/nbclient/client.py", line 862, in _check_raise_for_error
    raise CellExecutionError.from_cell_and_msg(cell, exec_reply_content)
nbclient.exceptions.CellExecutionError: An error occurred while executing the following cell:
------------------
import folium
------------------

[0;31m---------------------------------------------------------------------------[0m
[0;31mModuleNotFoundError[0m                       Traceback (most recent call last)
Input [0;32mIn [9][0m, in [0;36m<module>[0;34m[0m
[0;32m----> 1[0m [38;5;28;01mimport[39;00m [38;5;21;01mfolium[39;00m

[0;31mModuleNotFoundError[0m: No module named 'folium'
ModuleNotFoundError: No module named 'folium'

